Workbook
Name euro: 'Calc 1'!$I$1
Name euro: 'Calc 2'!$I$1
Name euro: 'Calc 3'!$I$1
Name euro: 'Calc 4'!$I$1
Name euro: #REF!
Name euro: #REF!
Name fee: 'Calc 1'!$E$1
Name fee: 'Calc 2'!$E$1
Name fee: 'Calc 3'!$E$1
Name fee: 'Calc 4'!$E$1
Name fee: [1]ExpoGlobal!$E$1
Name fee: #REF!
Name koop: 'Calc 1'!$F$1
Name koop: 'Calc 2'!$F$1
Name koop: 'Calc 3'!$F$1
Name koop: 'Calc 4'!$F$1
Name koop: #REF!
Name koop: #REF!
Name rate: 'Calc 1'!$F$1
Name rate: 'Calc 2'!$F$1
Name rate: 'Calc 3'!$F$1
Name rate: 'Calc 4'!$F$1
Name rate: #REF!
Name rate: #REF!
Name uk: 'Calc 1'!$E$1
Name uk: 'Calc 2'!$E$1
Name uk: 'Calc 3'!$E$1
Name uk: 'Calc 4'!$E$1
Name uk: #REF!
Name uk: #REF!
Name us: 'Calc 1'!$F$1
Name us: 'Calc 2'!$F$1
Name us: 'Calc 3'!$F$1
Name us: 'Calc 4'!$F$1
Name us: #REF!
Name us: #REF!

Sheet Budget show 1
C2: Budget sheet
C4: Client | E4: Name
C5: Show | E5: show
C6: Dates | E6: Month ##-##, 2025
C7: City, country | E7: Place, Country
C8: Project nummer | E8: Project nummer (Hubspot)
C10: Stand space m2 | E10: 0
C11: Single/double | E11: <kies type>
C12: Stand type | E12: <kies type>
C14: Standbuilder | E14: -
C15: Designer | E15: -
C16: Designer | E16: -
C17: 3rd party | E17: -
C19: Budget in US $ | E19: 0 | G19: Budget in Euro | I19: 0
C20: Rate | E20: 0 | G20: In- or decrease | I20: 0
C21: Date rate | E21: 00-00-0000 | G21: Target sell price / all-in | I21: =I19+I20 -> 0
C23: Services | E23: Costs | G23: Margin | I23: Sell services | K23: Fee
C24: Provision AV | E24: 0 | G24: =I24-E24 -> 0 | I24: =((E24*K24)/100)+E24 -> 0 | K24: 30 | L24: %
C25: Provision services | E25: 0 | G25: =I25-E25 -> 0 | I25: =((E25*K25)/100)+E25 -> 0 | K25: 10 | L25: %
C26: <item> | E26: 0 | G26: =I26-E26 -> 0 | I26: =((E26*K26)/100)+E26 -> 0 | K26: 30 | L26: %
C27: <item> | E27: 0 | G27: =I27-E27 -> 0 | I27: =((E27*K27)/100)+E27 -> 0 | K27: 30 | L27: %
C28: Total services | E28: =SUM(E24:E27) -> 0 | G28: =SUM(G24:G27) -> 0 | I28: =SUM(I24:I27) -> 0
G29: =IFERROR(G28/I28,0) -> 0
G31: Budget excluding services | I31: =I21-I28 -> 0
C33: PM costs | E33: Costs | G33: Margin | I33: Sell PM | K33: Factor
C34: Costs PM [project del.] | E34: 0 | G34: =I34-E34 -> 0 | I34: =E34*K34 -> 0 | K34: 4 | L34: factor
C35: Actual Costs PM [project del.] | E35: 0 | G35: =I35-E35 -> 0 | I35: =E35*K35 -> 0 | K35: 0 | L35: factor
C36: Costs PM Internal - preperation - EvR | E36: 0 | G36: =I36-E36 -> 0 | I36: =E36*K36 -> 0 | K36: 0 | L36: factor
C37: Costs PM Internal on site delivery - EvR | E37: 0 | G37: =I37-E37 -> 0 | I37: =E37*K37 -> 0 | K37: 0 | L37: factor
C38: Costs PM External FL preparation - EvR | E38: 0 | G38: =I38-E38 -> 0 | I38: =E38*K38 -> 0 | K38: 0 | L38: factor
C39: Costs PM External on site delivery - EvR | E39: 0 | G39: =I39-E39 -> 0 | I39: =E39*K39 -> 0 | K39: 0 | L39: factor
C40: Costs sales [pitch] | E40: 0 | G40: =I40-E40 -> 0 | I40: =E40*K40 -> 0 | K40: 0 | L40: factor
C41: Design [go-fee] | E41: 0 | G41: =I41-E41 -> 0 | I41: =E41*K41 -> 0 | K41: 0 | L41: factor
C42: Design [no-go fee] | E42: 0 | G42: =I42-E42 -> 0 | I42: =E42*K42 -> 0 | K42: 0 | L42: factor
C43: Design [no-go fee] | E43: 0 | G43: =I43-E43 -> 0 | I43: =E43*K43 -> 0 | K43: 0 | L43: factor
C44: Kick-back fee | E44: 0 | G44: =I44-E44 -> 0 | I44: =E44*K44 -> 0 | K44: 0 | L44: factor
C45: Insurance [% from stand sell] | E45: ='Budget show 1'!F223*0.005 -> 0 | G45: =I45-E45 -> 0
C46: Total PM + Design | E46: =SUM(E34:E45) -> 0 | G46: =SUM(G34:G45) -> 0 | I46: =SUM(I34:I45) -> 0
G47: =IFERROR(G46/I46,0) -> 0
G49: Budget excl. services & PM | I49: =I31-I46 -> 0
...

Sheet Budget show 2
C2: Budget sheet
C4: Client | E4: name
C5: Show | E5: show
C6: Dates | E6: Month ##-##, 2025
C7: City, country | E7: Place, Country
C8: Project nummer | E8: Project nummer (Hubspot)
C10: Stand space m2 | E10: 0
C11: Single/double | E11: <kies type>
C12: Stand type | E12: <kies type>
C14: Standbuilder | E14: -
C15: Designer | E15: -
C16: Designer | E16: -
C17: 3rd party | E17: -
C19: Budget in US $ | E19: 0 | G19: Budget in Euro | I19: 0
C20: Rate | E20: 0 | G20: In- or decrease | I20: 0
C21: Date rate | E21: 00-00-0000 | G21: Target sell price / all-in | I21: =I19+I20 -> 0
C23: Services | E23: Costs | G23: Margin | I23: Sell services | K23: Fee
C24: Provision AV | E24: 0 | G24: =I24-E24 -> 0 | I24: =((E24*K24)/100)+E24 -> 0 | K24: 30 | L24: %
C25: Provision services | E25: 0 | G25: =I25-E25 -> 0 | I25: =((E25*K25)/100)+E25 -> 0 | K25: 10 | L25: %
C26: <item> | E26: 0 | G26: =I26-E26 -> 0 | I26: =((E26*K26)/100)+E26 -> 0 | K26: 30 | L26: %
C27: <item> | E27: 0 | G27: =I27-E27 -> 0 | I27: =((E27*K27)/100)+E27 -> 0 | K27: 30 | L27: %
C28: Total services | E28: =SUM(E24:E27) -> 0 | G28: =SUM(G24:G27) -> 0 | I28: =SUM(I24:I27) -> 0
G29: =IFERROR(G28/I28,0) -> 0
G31: Budget excluding services | I31: =I21-I28 -> 0
C33: PM costs | E33: Costs | G33: Margin | I33: Sell PM | K33: Factor
C34: Costs PM [project del.] | E34: 0 | G34: =I34-E34 -> 0 | I34: =E34*K34 -> 0 | K34: 4 | L34: factor
C35: Actual Costs PM [project del.] | E35: 0 | G35: =I35-E35 -> 0 | I35: =E35*K35 -> 0 | K35: 0 | L35: factor
C36: Costs PM Internal - preperation - EvR | E36: 0 | G36: =I36-E36 -> 0 | I36: =E36*K36 -> 0 | K36: 0 | L36: factor
C37: Costs PM Internal on site delivery - EvR | E37: 0 | G37: =I37-E37 -> 0 | I37: =E37*K37 -> 0 | K37: 0 | L37: factor
C38: Costs PM External FL preparation - EvR | E38: 0 | G38: =I38-E38 -> 0 | I38: =E38*K38 -> 0 | K38: 0 | L38: factor
C39: Costs PM External on site delivery - EvR | E39: 0 | G39: =I39-E39 -> 0 | I39: =E39*K39 -> 0 | K39: 0 | L39: factor
C40: Costs sales [pitch] | E40: 0 | G40: =I40-E40 -> 0 | I40: =E40*K40 -> 0 | K40: 0 | L40: factor
C41: Design [go-fee] | E41: 0 | G41: =I41-E41 -> 0 | I41: =E41*K41 -> 0 | K41: 0 | L41: factor
C42: Design [no-go fee] | E42: 0 | G42: =I42-E42 -> 0 | I42: =E42*K42 -> 0 | K42: 0 | L42: factor
C43: Design [no-go fee] | E43: 0 | G43: =I43-E43 -> 0 | I43: =E43*K43 -> 0 | K43: 0 | L43: factor
C44: Kick-back fee | E44: 0 | G44: =I44-E44 -> 0 | I44: =E44*K44 -> 0 | K44: 0 | L44: factor
C45: Insurance [% from stand sell] | E45: ='Budget show 2'!F223*0.005 -> 0 | G45: =I45-E45 -> 0
C46: Total PM + Design | E46: =SUM(E34:E45) -> 0 | G46: =SUM(G34:G45) -> 0 | I46: =SUM(I34:I45) -> 0
G47: =IFERROR(G46/I46,0) -> 0
G49: Budget excl. services & PM | I49: =I31-I46 -> 0
...

Sheet Budget show 3
C2: Budget sheet
C4: Client | E4: name
C5: Show | E5: show
C6: Dates | E6: Month ##-##, 2025
C7: City, country | E7: Place, Country
C8: Project nummer | E8: Project nummer (Hubspot)
C10: Stand space m2 | E10: 0
C11: Single/double | E11: <kies type>
C12: Stand type | E12: <kies type>
C14: Standbuilder | E14: -
C15: Designer | E15: -
C16: Designer | E16: -
C17: 3rd party | E17: -
C19: Budget in US $ | E19: 0 | G19: Budget in Euro | I19: 0
C20: Rate | E20: 0 | G20: In- or decrease | I20: 0
C21: Date rate | E21: 00-00-0000 | G21: Target sell price / all-in | I21: =I19+I20 -> 0
C23: Services | E23: Costs | G23: Margin | I23: Sell services | K23: Fee
C24: Provision AV | E24: 0 | G24: =I24-E24 -> 0 | I24: =((E24*K24)/100)+E24 -> 0 | K24: 30 | L24: %
C25: Provision services | E25: 0 | G25: =I25-E25 -> 0 | I25: =((E25*K25)/100)+E25 -> 0 | K25: 10 | L25: %
C26: <item> | E26: 0 | G26: =I26-E26 -> 0 | I26: =((E26*K26)/100)+E26 -> 0 | K26: 30 | L26: %
C27: <item> | E27: 0 | G27: =I27-E27 -> 0 | I27: =((E27*K27)/100)+E27 -> 0 | K27: 30 | L27: %
C28: Total services | E28: =SUM(E24:E27) -> 0 | G28: =SUM(G24:G27) -> 0 | I28: =SUM(I24:I27) -> 0
G29: =IFERROR(G28/I28,0) -> 0
G31: Budget excluding services | I31: =I21-I28 -> 0
C33: PM costs | E33: Costs | G33: Margin | I33: Sell PM | K33: Factor
C34: Costs PM [project del.] | E34: 0 | G34: =I34-E34 -> 0 | I34: =E34*K34 -> 0 | K34: 4 | L34: factor
C35: Actual Costs PM [project del.] | E35: 0 | G35: =I35-E35 -> 0 | I35: =E35*K35 -> 0 | K35: 0 | L35: factor
C36: Costs PM Internal - preperation - EvR | E36: 0 | G36: =I36-E36 -> 0 | I36: =E36*K36 -> 0 | K36: 0 | L36: factor
C37: Costs PM Internal on site delivery - EvR | E37: 0 | G37: =I37-E37 -> 0 | I37: =E37*K37 -> 0 | K37: 0 | L37: factor
C38: Costs PM External FL preparation - EvR | E38: 0 | G38: =I38-E38 -> 0 | I38: =E38*K38 -> 0 | K38: 0 | L38: factor
C39: Costs PM External on site delivery - EvR | E39: 0 | G39: =I39-E39 -> 0 | I39: =E39*K39 -> 0 | K39: 0 | L39: factor
C40: Costs sales [pitch] | E40: 0 | G40: =I40-E40 -> 0 | I40: =E40*K40 -> 0 | K40: 0 | L40: factor
C41: Design [go-fee] | E41: 0 | G41: =I41-E41 -> 0 | I41: =E41*K41 -> 0 | K41: 0 | L41: factor
C42: Design [no-go fee] | E42: 0 | G42: =I42-E42 -> 0 | I42: =E42*K42 -> 0 | K42: 0 | L42: factor
C43: Design [no-go fee] | E43: 0 | G43: =I43-E43 -> 0 | I43: =E43*K43 -> 0 | K43: 0 | L43: factor
C44: Kick-back fee | E44: 0 | G44: =I44-E44 -> 0 | I44: =E44*K44 -> 0 | K44: 0 | L44: factor
C45: Insurance [% from stand sell] | E45: ='Budget show 3'!F223*0.005 -> 0 | G45: =I45-E45 -> 0
C46: Total PM + Design | E46: =SUM(E34:E45) -> 0 | G46: =SUM(G34:G45) -> 0 | I46: =SUM(I34:I45) -> 0
G47: =IFERROR(G46/I46,0) -> 0
G49: Budget excl. services & PM | I49: =I31-I46 -> 0
...

Sheet Budget show 4
C2: Budget sheet
C4: Client | E4: name
C5: Show | E5: show
C6: Dates | E6: Month ##-##, 2025
C7: City, country | E7: Place, Country
C8: Project nummer | E8: Project nummer (Hubspot)
C10: Stand space m2 | E10: 0
C11: Single/double | E11: <kies type>
C12: Stand type | E12: <kies type>
C14: Standbuilder | E14: -
C15: Designer | E15: -
C16: Designer | E16: -
C17: 3rd party | E17: -
C19: Budget in US $ | E19: 0 | G19: Budget in Euro | I19: 0
C20: Rate | E20: 0 | G20: In- or decrease | I20: 0
C21: Date rate | E21: 00-00-0000 | G21: Target sell price / all-in | I21: =I19+I20 -> 0
C23: Services | E23: Costs | G23: Margin | I23: Sell services | K23: Fee
C24: Provision AV | E24: 0 | G24: =I24-E24 -> 0 | I24: =((E24*K24)/100)+E24 -> 0 | K24: 30 | L24: %
C25: Provision services | E25: 0 | G25: =I25-E25 -> 0 | I25: =((E25*K25)/100)+E25 -> 0 | K25: 10 | L25: %
C26: <item> | E26: 0 | G26: =I26-E26 -> 0 | I26: =((E26*K26)/100)+E26 -> 0 | K26: 30 | L26: %
C27: <item> | E27: 0 | G27: =I27-E27 -> 0 | I27: =((E27*K27)/100)+E27 -> 0 | K27: 30 | L27: %
C28: Total services | E28: =SUM(E24:E27) -> 0 | G28: =SUM(G24:G27) -> 0 | I28: =SUM(I24:I27) -> 0
G29: =IFERROR(G28/I28,0) -> 0
G31: Budget excluding services | I31: =I21-I28 -> 0
C33: PM costs | E33: Costs | G33: Margin | I33: Sell PM | K33: Factor
C34: Costs PM [project del.] | E34: 0 | G34: =I34-E34 -> 0 | I34: =E34*K34 -> 0 | K34: 4 | L34: factor
C35: Actual Costs PM [project del.] | E35: 0 | G35: =I35-E35 -> 0 | I35: =E35*K35 -> 0 | K35: 0 | L35: factor
C36: Costs PM Internal - preperation - EvR | E36: 0 | G36: =I36-E36 -> 0 | I36: =E36*K36 -> 0 | K36: 0 | L36: factor
C37: Costs PM Internal on site delivery - EvR | E37: 0 | G37: =I37-E37 -> 0 | I37: =E37*K37 -> 0 | K37: 0 | L37: factor
C38: Costs PM External FL preparation - EvR | E38: 0 | G38: =I38-E38 -> 0 | I38: =E38*K38 -> 0 | K38: 0 | L38: factor
C39: Costs PM External on site delivery - EvR | E39: 0 | G39: =I39-E39 -> 0 | I39: =E39*K39 -> 0 | K39: 0 | L39: factor
C40: Costs sales [pitch] | E40: 0 | G40: =I40-E40 -> 0 | I40: =E40*K40 -> 0 | K40: 0 | L40: factor
C41: Design [go-fee] | E41: 0 | G41: =I41-E41 -> 0 | I41: =E41*K41 -> 0 | K41: 0 | L41: factor
C42: Design [no-go fee] | E42: 0 | G42: =I42-E42 -> 0 | I42: =E42*K42 -> 0 | K42: 0 | L42: factor
C43: Design [no-go fee] | E43: 0 | G43: =I43-E43 -> 0 | I43: =E43*K43 -> 0 | K43: 0 | L43: factor
C44: Kick-back fee | E44: 0 | G44: =I44-E44 -> 0 | I44: =E44*K44 -> 0 | K44: 0 | L44: factor
C45: Insurance [% from stand sell] | E45: ='Budget show 4'!F223*0.005 -> 0 | G45: =I45-E45 -> 0
C46: Total PM + Design | E46: =SUM(E34:E45) -> 0 | G46: =SUM(G34:G45) -> 0 | I46: =SUM(I34:I45) -> 0
G47: =IFERROR(G46/I46,0) -> 0
G49: Budget excl. services & PM | I49: =I31-I46 -> 0
...

Sheet Calc 1
D1: fee | E1: 1.3
B2: Description | D2: Tot. costs | E2: Margin | F2: Sell €
B4: ='Budget show 1'!E4 -> Name | D4: Green | E4: = to be filled in
B5: ='Budget show 1'!E5 -> show | D5: Blue | E5: = automatically filled in
B6: ='Budget show 1'!E6 -> Month ##-##, 2025
B7: ='Budget show 1'!E7 -> Place, Country
B8: ='Budget show 1'!E8 -> Project nummer (Hubspot)
D9: Date offer | E9: Builder | F9: Offer nr. | H9: m2 previous | I9: Difference
A10: ='Budget show 1'!E10 -> 0 | B10: m2 | D10: ##-##-2025 | E10: ='Budget show 1'!E14 -> - | F10: ## | H10: 0 | I10: =A10-H10 -> 0
B12: Rental elements
B14: Floor | H14: Previous | I14: Difference
A15: 0 | B15: x | D15: 0 | E15: =F15-D15 -> 0 | F15: =ROUNDUP((D15*fee/5),0)*5 -> 0 | H15: 0 | I15: =F15-H15 -> 0
A16: 0 | B16: x | D16: 0 | E16: =F16-D16 -> 0 | F16: =ROUNDUP((D16*fee/5),0)*5 -> 0 | H16: 0 | I16: =F16-H16 -> 0
A17: 0 | B17: x | D17: 0 | E17: =F17-D17 -> 0 | F17: =ROUNDUP((D17*fee/5),0)*5 -> 0 | H17: 0 | I17: =F17-H17 -> 0
A18: 0 | B18: x | D18: 0 | E18: =F18-D18 -> 0 | F18: =ROUNDUP((D18*fee/5),0)*5 -> 0 | H18: 0 | I18: =F18-H18 -> 0
A19: 0 | B19: x | D19: 0 | E19: =F19-D19 -> 0 | F19: =ROUNDUP((D19*fee/5),0)*5 -> 0 | H19: 0 | I19: =F19-H19 -> 0
A20: 0 | B20: x | D20: 0 | E20: =F20-D20 -> 0 | F20: =ROUNDUP((D20*fee/5),0)*5 -> 0 | H20: 0 | I20: =F20-H20 -> 0
A22: 0 | B22: x increase amount | D22: 0 | E22: =F22-D22 -> 0 | F22: 0 | H22: 0 | I22: =F22-H22 -> 0
B25: =B14 -> Floor | D25: =SUM(D15:D24) -> 0 | E25: =SUM(E15:E24) -> 0 | F25: =SUM(F15:F24) -> 0 | H25: =SUM(H15:H24) -> 0 | I25: =F25-H25 -> 0
B28: Walls | H28: Previous | I28: Difference
A29: 0 | B29: x | D29: 0 | E29: =F29-D29 -> 0 | F29: =ROUNDUP((D29*fee/5),0)*5 -> 0 | H29: 0 | I29: =F29-H29 -> 0
A30: 0 | B30: x | D30: 0 | E30: =F30-D30 -> 0 | F30: =ROUNDUP((D30*fee/5),0)*5 -> 0 | H30: 0 | I30: =F30-H30 -> 0
A31: 0 | B31: x | D31: 0 | E31: =F31-D31 -> 0 | F31: =ROUNDUP((D31*fee/5),0)*5 -> 0 | H31: 0 | I31: =F31-H31 -> 0
A32: 0 | B32: x | D32: 0 | E32: =F32-D32 -> 0 | F32: =ROUNDUP((D32*fee/5),0)*5 -> 0 | H32: 0 | I32: =F32-H32 -> 0
A33: 0 | B33: x | D33: 0 | E33: =F33-D33 -> 0 | F33: =ROUNDUP((D33*fee/5),0)*5 -> 0 | H33: 0 | I33: =F33-H33 -> 0
A34: 0 | B34: x | D34: 0 | E34: =F34-D34 -> 0 | F34: =ROUNDUP((D34*fee/5),0)*5 -> 0 | H34: 0 | I34: =F34-H34 -> 0
A35: 0 | B35: x | D35: 0 | E35: =F35-D35 -> 0 | F35: =ROUNDUP((D35*fee/5),0)*5 -> 0 | H35: 0 | I35: =F35-H35 -> 0
A36: 0 | B36: x | D36: 0 | E36: =F36-D36 -> 0 | F36: =ROUNDUP((D36*fee/5),0)*5 -> 0 | H36: 0 | I36: =F36-H36 -> 0
A37: 0 | B37: x | D37: 0 | E37: =F37-D37 -> 0 | F37: =ROUNDUP((D37*fee/5),0)*5 -> 0 | H37: 0 | I37: =F37-H37 -> 0
A39: 0 | B39: x increase amount | D39: 0 | E39: =F39-D39 -> 0 | F39: 0 | H39: 0 | I39: =F39-H39 -> 0
B41: =B28 -> Walls | D41: =SUM(D29:D40) -> 0 | E41: =SUM(E29:E40) -> 0 | F41: =SUM(F29:F40) -> 0 | H41: =SUM(H29:H40) -> 0 | I41: =F41-H41 -> 0
B44: Rigging | H44: Previous | I44: Difference
A45: 0 | B45: x | D45: 0 | E45: =F45-D45 -> 0 | F45: =ROUNDUP((D45*fee/5),0)*5 -> 0 | H45: 0 | I45: =F45-H45 -> 0
A46: 0 | B46: x | D46: 0 | E46: =F46-D46 -> 0 | F46: =ROUNDUP((D46*fee/5),0)*5 -> 0 | H46: 0 | I46: =F46-H46 -> 0
A47: 0 | B47: x | D47: 0 | E47: =F47-D47 -> 0 | F47: =ROUNDUP((D47*fee/5),0)*5 -> 0 | H47: 0 | I47: =F47-H47 -> 0
B49: =B44 -> Rigging | D49: =SUM(D45:D48) -> 0 | E49: =SUM(E45:E48) -> 0 | F49: =SUM(F45:F48) -> 0 | H49: =SUM(H45:H48) -> 0 | I49: =F49-H49 -> 0
B52: Pantry | H52: Previous | I52: Difference
A53: 0 | B53: x | D53: 0 | E53: =F53-D53 -> 0 | F53: =ROUNDUP((D53*fee/5),0)*5 -> 0 | H53: 0 | I53: =F53-H53 -> 0
A54: 0 | B54: x | D54: 0 | E54: =F54-D54 -> 0 | F54: =ROUNDUP((D54*fee/5),0)*5 -> 0 | H54: 0 | I54: =F54-H54 -> 0
A55: 0 | B55: x | D55: 0 | E55: =F55-D55 -> 0 | F55: =ROUNDUP((D55*fee/5),0)*5 -> 0 | H55: 0 | I55: =F55-H55 -> 0
...

Sheet Calc 2
D1: fee | E1: 1.3
B2: Description | D2: Tot. costs | E2: Margin | F2: Sell €
B4: ='Budget show 2'!E4 -> name | D4: Green | E4: = to be filled in
B5: ='Budget show 2'!E5 -> show | D5: Blue | E5: = automatically filled in
B6: ='Budget show 2'!E6 -> Month ##-##, 2025
B7: ='Budget show 2'!E7 -> Place, Country
B8: ='Budget show 2'!E8 -> Project nummer (Hubspot)
D9: Date offer | E9: Builder | F9: Offer nr. | H9: m2 previous | I9: Difference
A10: ='Budget show 2'!E10 -> 0 | B10: m2 | D10: ##-##-2025 | E10: ='Budget show 2'!E14 -> - | F10: ## | H10: 0 | I10: =A10-H10 -> 0
B12: Rental elements
B14: Floor | H14: Previous | I14: Difference
A15: 0 | B15: x | D15: 1 | E15: =F15-D15 -> 4 | F15: =ROUNDUP((D15*fee/5),0)*5 -> 5 | H15: 0 | I15: =F15-H15 -> 5
A16: 0 | B16: x | D16: 0 | E16: =F16-D16 -> 0 | F16: =ROUNDUP((D16*fee/5),0)*5 -> 0 | H16: 0 | I16: =F16-H16 -> 0
A17: 0 | B17: x | D17: 0 | E17: =F17-D17 -> 0 | F17: =ROUNDUP((D17*fee/5),0)*5 -> 0 | H17: 0 | I17: =F17-H17 -> 0
A18: 0 | B18: x | D18: 0 | E18: =F18-D18 -> 0 | F18: =ROUNDUP((D18*fee/5),0)*5 -> 0 | H18: 0 | I18: =F18-H18 -> 0
A19: 0 | B19: x | D19: 0 | E19: =F19-D19 -> 0 | F19: =ROUNDUP((D19*fee/5),0)*5 -> 0 | H19: 0 | I19: =F19-H19 -> 0
A20: 0 | B20: x | D20: 0 | E20: =F20-D20 -> 0 | F20: =ROUNDUP((D20*fee/5),0)*5 -> 0 | H20: 0 | I20: =F20-H20 -> 0
A22: 0 | B22: x increase amount | D22: 0 | E22: =F22-D22 -> 0 | F22: 0 | H22: 0 | I22: =F22-H22 -> 0
B25: =B14 -> Floor | D25: =SUM(D15:D24) -> 1 | E25: =SUM(E15:E24) -> 4 | F25: =SUM(F15:F24) -> 5 | H25: =SUM(H15:H24) -> 0 | I25: =F25-H25 -> 5
B28: Walls | H28: Previous | I28: Difference
A29: 0 | B29: x | D29: 0 | E29: =F29-D29 -> 0 | F29: =ROUNDUP((D29*fee/5),0)*5 -> 0 | H29: 0 | I29: =F29-H29 -> 0
A30: 0 | B30: x | D30: 0 | E30: =F30-D30 -> 0 | F30: =ROUNDUP((D30*fee/5),0)*5 -> 0 | H30: 0 | I30: =F30-H30 -> 0
A31: 0 | B31: x | D31: 0 | E31: =F31-D31 -> 0 | F31: =ROUNDUP((D31*fee/5),0)*5 -> 0 | H31: 0 | I31: =F31-H31 -> 0
A32: 0 | B32: x | D32: 0 | E32: =F32-D32 -> 0 | F32: =ROUNDUP((D32*fee/5),0)*5 -> 0 | H32: 0 | I32: =F32-H32 -> 0
A33: 0 | B33: x | D33: 0 | E33: =F33-D33 -> 0 | F33: =ROUNDUP((D33*fee/5),0)*5 -> 0 | H33: 0 | I33: =F33-H33 -> 0
A34: 0 | B34: x | D34: 0 | E34: =F34-D34 -> 0 | F34: =ROUNDUP((D34*fee/5),0)*5 -> 0 | H34: 0 | I34: =F34-H34 -> 0
A35: 0 | B35: x | D35: 0 | E35: =F35-D35 -> 0 | F35: =ROUNDUP((D35*fee/5),0)*5 -> 0 | H35: 0 | I35: =F35-H35 -> 0
A36: 0 | B36: x | D36: 0 | E36: =F36-D36 -> 0 | F36: =ROUNDUP((D36*fee/5),0)*5 -> 0 | H36: 0 | I36: =F36-H36 -> 0
A37: 0 | B37: x | D37: 0 | E37: =F37-D37 -> 0 | F37: =ROUNDUP((D37*fee/5),0)*5 -> 0 | H37: 0 | I37: =F37-H37 -> 0
A39: 0 | B39: x increase amount | D39: 0 | E39: =F39-D39 -> 0 | F39: 0 | H39: 0 | I39: =F39-H39 -> 0
B41: =B28 -> Walls | D41: =SUM(D29:D40) -> 0 | E41: =SUM(E29:E40) -> 0 | F41: =SUM(F29:F40) -> 0 | H41: =SUM(H29:H40) -> 0 | I41: =F41-H41 -> 0
B44: Rigging | H44: Previous | I44: Difference
A45: 0 | B45: x | D45: 0 | E45: =F45-D45 -> 0 | F45: =ROUNDUP((D45*fee/5),0)*5 -> 0 | H45: 0 | I45: =F45-H45 -> 0
A46: 0 | B46: x | D46: 0 | E46: =F46-D46 -> 0 | F46: =ROUNDUP((D46*fee/5),0)*5 -> 0 | H46: 0 | I46: =F46-H46 -> 0
A47: 0 | B47: x | D47: 0 | E47: =F47-D47 -> 0 | F47: =ROUNDUP((D47*fee/5),0)*5 -> 0 | H47: 0 | I47: =F47-H47 -> 0
B49: =B44 -> Rigging | D49: =SUM(D45:D48) -> 0 | E49: =SUM(E45:E48) -> 0 | F49: =SUM(F45:F48) -> 0 | H49: =SUM(H45:H48) -> 0 | I49: =F49-H49 -> 0
B52: Pantry | H52: Previous | I52: Difference
A53: 0 | B53: x | D53: 0 | E53: =F53-D53 -> 0 | F53: =ROUNDUP((D53*fee/5),0)*5 -> 0 | H53: 0 | I53: =F53-H53 -> 0
A54: 0 | B54: x | D54: 0 | E54: =F54-D54 -> 0 | F54: =ROUNDUP((D54*fee/5),0)*5 -> 0 | H54: 0 | I54: =F54-H54 -> 0
A55: 0 | B55: x | D55: 0 | E55: =F55-D55 -> 0 | F55: =ROUNDUP((D55*fee/5),0)*5 -> 0 | H55: 0 | I55: =F55-H55 -> 0
...

Sheet Calc 3
D1: fee | E1: 1.3
B2: Description | D2: Tot. costs | E2: Margin | F2: Sell €
B4: ='Budget show 3'!E4 -> name | D4: Green | E4: = to be filled in
B5: ='Budget show 3'!E5 -> show | D5: Blue | E5: = automatically filled in
B6: ='Budget show 3'!E6 -> Month ##-##, 2025
B7: ='Budget show 3'!E7 -> Place, Country
B8: ='Budget show 3'!E8 -> Project nummer (Hubspot)
D9: Date offer | E9: Builder | F9: Offer nr. | H9: m2 previous | I9: Difference
A10: ='Budget show 3'!E10 -> 0 | B10: m2 | D10: ##-##-2025 | E10: ='Budget show 3'!E14 -> - | F10: ## | H10: 0 | I10: =A10-H10 -> 0
B12: Rental elements
B14: Floor | H14: Previous | I14: Difference
A15: 0 | B15: x | D15: 0 | E15: =F15-D15 -> 0 | F15: =ROUNDUP((D15*fee/5),0)*5 -> 0 | H15: 0 | I15: =F15-H15 -> 0
A16: 0 | B16: x | D16: 0 | E16: =F16-D16 -> 0 | F16: =ROUNDUP((D16*fee/5),0)*5 -> 0 | H16: 0 | I16: =F16-H16 -> 0
A17: 0 | B17: x | D17: 0 | E17: =F17-D17 -> 0 | F17: =ROUNDUP((D17*fee/5),0)*5 -> 0 | H17: 0 | I17: =F17-H17 -> 0
A18: 0 | B18: x | D18: 0 | E18: =F18-D18 -> 0 | F18: =ROUNDUP((D18*fee/5),0)*5 -> 0 | H18: 0 | I18: =F18-H18 -> 0
A19: 0 | B19: x | D19: 0 | E19: =F19-D19 -> 0 | F19: =ROUNDUP((D19*fee/5),0)*5 -> 0 | H19: 0 | I19: =F19-H19 -> 0
A20: 0 | B20: x | D20: 0 | E20: =F20-D20 -> 0 | F20: =ROUNDUP((D20*fee/5),0)*5 -> 0 | H20: 0 | I20: =F20-H20 -> 0
A22: 0 | B22: x increase amount | D22: 0 | E22: =F22-D22 -> 0 | F22: 0 | H22: 0 | I22: =F22-H22 -> 0
B25: =B14 -> Floor | D25: =SUM(D15:D24) -> 0 | E25: =SUM(E15:E24) -> 0 | F25: =SUM(F15:F24) -> 0 | H25: =SUM(H15:H24) -> 0 | I25: =F25-H25 -> 0
B28: Walls | H28: Previous | I28: Difference
A29: 0 | B29: x | D29: 0 | E29: =F29-D29 -> 0 | F29: =ROUNDUP((D29*fee/5),0)*5 -> 0 | H29: 0 | I29: =F29-H29 -> 0
A30: 0 | B30: x | D30: 0 | E30: =F30-D30 -> 0 | F30: =ROUNDUP((D30*fee/5),0)*5 -> 0 | H30: 0 | I30: =F30-H30 -> 0
A31: 0 | B31: x | D31: 0 | E31: =F31-D31 -> 0 | F31: =ROUNDUP((D31*fee/5),0)*5 -> 0 | H31: 0 | I31: =F31-H31 -> 0
A32: 0 | B32: x | D32: 0 | E32: =F32-D32 -> 0 | F32: =ROUNDUP((D32*fee/5),0)*5 -> 0 | H32: 0 | I32: =F32-H32 -> 0
A33: 0 | B33: x | D33: 0 | E33: =F33-D33 -> 0 | F33: =ROUNDUP((D33*fee/5),0)*5 -> 0 | H33: 0 | I33: =F33-H33 -> 0
A34: 0 | B34: x | D34: 0 | E34: =F34-D34 -> 0 | F34: =ROUNDUP((D34*fee/5),0)*5 -> 0 | H34: 0 | I34: =F34-H34 -> 0
A35: 0 | B35: x | D35: 0 | E35: =F35-D35 -> 0 | F35: =ROUNDUP((D35*fee/5),0)*5 -> 0 | H35: 0 | I35: =F35-H35 -> 0
A36: 0 | B36: x | D36: 0 | E36: =F36-D36 -> 0 | F36: =ROUNDUP((D36*fee/5),0)*5 -> 0 | H36: 0 | I36: =F36-H36 -> 0
A37: 0 | B37: x | D37: 0 | E37: =F37-D37 -> 0 | F37: =ROUNDUP((D37*fee/5),0)*5 -> 0 | H37: 0 | I37: =F37-H37 -> 0
A39: 0 | B39: x increase amount | D39: 0 | E39: =F39-D39 -> 0 | F39: 0 | H39: 0 | I39: =F39-H39 -> 0
B41: =B28 -> Walls | D41: =SUM(D29:D40) -> 0 | E41: =SUM(E29:E40) -> 0 | F41: =SUM(F29:F40) -> 0 | H41: =SUM(H29:H40) -> 0 | I41: =F41-H41 -> 0
B44: Rigging | H44: Previous | I44: Difference
A45: 0 | B45: x | D45: 0 | E45: =F45-D45 -> 0 | F45: =ROUNDUP((D45*fee/5),0)*5 -> 0 | H45: 0 | I45: =F45-H45 -> 0
A46: 0 | B46: x | D46: 0 | E46: =F46-D46 -> 0 | F46: =ROUNDUP((D46*fee/5),0)*5 -> 0 | H46: 0 | I46: =F46-H46 -> 0
A47: 0 | B47: x | D47: 0 | E47: =F47-D47 -> 0 | F47: =ROUNDUP((D47*fee/5),0)*5 -> 0 | H47: 0 | I47: =F47-H47 -> 0
B49: =B44 -> Rigging | D49: =SUM(D45:D48) -> 0 | E49: =SUM(E45:E48) -> 0 | F49: =SUM(F45:F48) -> 0 | H49: =SUM(H45:H48) -> 0 | I49: =F49-H49 -> 0
B52: Pantry | H52: Previous | I52: Difference
A53: 0 | B53: x | D53: 0 | E53: =F53-D53 -> 0 | F53: =ROUNDUP((D53*fee/5),0)*5 -> 0 | H53: 0 | I53: =F53-H53 -> 0
A54: 0 | B54: x | D54: 0 | E54: =F54-D54 -> 0 | F54: =ROUNDUP((D54*fee/5),0)*5 -> 0 | H54: 0 | I54: =F54-H54 -> 0
A55: 0 | B55: x | D55: 0 | E55: =F55-D55 -> 0 | F55: =ROUNDUP((D55*fee/5),0)*5 -> 0 | H55: 0 | I55: =F55-H55 -> 0
...

Sheet Calc 4
D1: fee | E1: 1.3
B2: Description | D2: Tot. costs | E2: Margin | F2: Sell €
B4: ='Budget show 4'!E4 -> name | D4: Green | E4: = to be filled in
B5: ='Budget show 4'!E5 -> show | D5: Blue | E5: = automatically filled in
B6: ='Budget show 4'!E6 -> Month ##-##, 2025
B7: ='Budget show 4'!E7 -> Place, Country
B8: ='Budget show 4'!E8 -> Project nummer (Hubspot)
D9: Date offer | E9: Builder | F9: Offer nr. | H9: m2 previous | I9: Difference
A10: ='Budget show 4'!E10 -> 0 | B10: m2 | D10: ##-##-2025 | E10: ='Budget show 4'!E14 -> - | F10: ## | H10: 0 | I10: =A10-H10 -> 0
B12: Rental elements
B14: Floor | H14: Previous | I14: Difference
A15: 0 | B15: x | D15: 0 | E15: =F15-D15 -> 0 | F15: =ROUNDUP((D15*fee/5),0)*5 -> 0 | H15: 0 | I15: =F15-H15 -> 0
A16: 0 | B16: x | D16: 0 | E16: =F16-D16 -> 0 | F16: =ROUNDUP((D16*fee/5),0)*5 -> 0 | H16: 0 | I16: =F16-H16 -> 0
A17: 0 | B17: x | D17: 0 | E17: =F17-D17 -> 0 | F17: =ROUNDUP((D17*fee/5),0)*5 -> 0 | H17: 0 | I17: =F17-H17 -> 0
A18: 0 | B18: x | D18: 0 | E18: =F18-D18 -> 0 | F18: =ROUNDUP((D18*fee/5),0)*5 -> 0 | H18: 0 | I18: =F18-H18 -> 0
A19: 0 | B19: x | D19: 0 | E19: =F19-D19 -> 0 | F19: =ROUNDUP((D19*fee/5),0)*5 -> 0 | H19: 0 | I19: =F19-H19 -> 0
A20: 0 | B20: x | D20: 0 | E20: =F20-D20 -> 0 | F20: =ROUNDUP((D20*fee/5),0)*5 -> 0 | H20: 0 | I20: =F20-H20 -> 0
A22: 0 | B22: x increase amount | D22: 0 | E22: =F22-D22 -> 0 | F22: 0 | H22: 0 | I22: =F22-H22 -> 0
B25: =B14 -> Floor | D25: =SUM(D15:D24) -> 0 | E25: =SUM(E15:E24) -> 0 | F25: =SUM(F15:F24) -> 0 | H25: =SUM(H15:H24) -> 0 | I25: =F25-H25 -> 0
B28: Walls | H28: Previous | I28: Difference
A29: 0 | B29: x | D29: 0 | E29: =F29-D29 -> 0 | F29: =ROUNDUP((D29*fee/5),0)*5 -> 0 | H29: 0 | I29: =F29-H29 -> 0
A30: 0 | B30: x | D30: 0 | E30: =F30-D30 -> 0 | F30: =ROUNDUP((D30*fee/5),0)*5 -> 0 | H30: 0 | I30: =F30-H30 -> 0
A31: 0 | B31: x | D31: 0 | E31: =F31-D31 -> 0 | F31: =ROUNDUP((D31*fee/5),0)*5 -> 0 | H31: 0 | I31: =F31-H31 -> 0
A32: 0 | B32: x | D32: 0 | E32: =F32-D32 -> 0 | F32: =ROUNDUP((D32*fee/5),0)*5 -> 0 | H32: 0 | I32: =F32-H32 -> 0
A33: 0 | B33: x | D33: 0 | E33: =F33-D33 -> 0 | F33: =ROUNDUP((D33*fee/5),0)*5 -> 0 | H33: 0 | I33: =F33-H33 -> 0
A34: 0 | B34: x | D34: 0 | E34: =F34-D34 -> 0 | F34: =ROUNDUP((D34*fee/5),0)*5 -> 0 | H34: 0 | I34: =F34-H34 -> 0
A35: 0 | B35: x | D35: 0 | E35: =F35-D35 -> 0 | F35: =ROUNDUP((D35*fee/5),0)*5 -> 0 | H35: 0 | I35: =F35-H35 -> 0
A36: 0 | B36: x | D36: 0 | E36: =F36-D36 -> 0 | F36: =ROUNDUP((D36*fee/5),0)*5 -> 0 | H36: 0 | I36: =F36-H36 -> 0
A37: 0 | B37: x | D37: 0 | E37: =F37-D37 -> 0 | F37: =ROUNDUP((D37*fee/5),0)*5 -> 0 | H37: 0 | I37: =F37-H37 -> 0
A39: 0 | B39: x increase amount | D39: 0 | E39: =F39-D39 -> 0 | F39: 0 | H39: 0 | I39: =F39-H39 -> 0
B41: =B28 -> Walls | D41: =SUM(D29:D40) -> 0 | E41: =SUM(E29:E40) -> 0 | F41: =SUM(F29:F40) -> 0 | H41: =SUM(H29:H40) -> 0 | I41: =F41-H41 -> 0
B44: Rigging | H44: Previous | I44: Difference
A45: 0 | B45: x | D45: 0 | E45: =F45-D45 -> 0 | F45: =ROUNDUP((D45*fee/5),0)*5 -> 0 | H45: 0 | I45: =F45-H45 -> 0
A46: 0 | B46: x | D46: 0 | E46: =F46-D46 -> 0 | F46: =ROUNDUP((D46*fee/5),0)*5 -> 0 | H46: 0 | I46: =F46-H46 -> 0
A47: 0 | B47: x | D47: 0 | E47: =F47-D47 -> 0 | F47: =ROUNDUP((D47*fee/5),0)*5 -> 0 | H47: 0 | I47: =F47-H47 -> 0
B49: =B44 -> Rigging | D49: =SUM(D45:D48) -> 0 | E49: =SUM(E45:E48) -> 0 | F49: =SUM(F45:F48) -> 0 | H49: =SUM(H45:H48) -> 0 | I49: =F49-H49 -> 0
B52: Pantry | H52: Previous | I52: Difference
A53: 0 | B53: x | D53: 0 | E53: =F53-D53 -> 0 | F53: =ROUNDUP((D53*fee/5),0)*5 -> 0 | H53: 0 | I53: =F53-H53 -> 0
A54: 0 | B54: x | D54: 0 | E54: =F54-D54 -> 0 | F54: =ROUNDUP((D54*fee/5),0)*5 -> 0 | H54: 0 | I54: =F54-H54 -> 0
A55: 0 | B55: x | D55: 0 | E55: =F55-D55 -> 0 | F55: =ROUNDUP((D55*fee/5),0)*5 -> 0 | H55: 0 | I55: =F55-H55 -> 0
...

Sheet Total overview
B2: Client | D2: Nr. of shows | F2: Builder: | G2: Concept:
B3: ='Budget show 1'!E4 | D3: 4 | F3: ='Budget show 1'!E14
B5: Project | C5: Purchase | D5: Margin | E5: Sell | F5: Budget | G5: Difference | I5: M2 | J5: Price/m2
B6: ='Budget show 1'!E5 -> show | C6: ='Calc 1'!D267 -> 0 | D6: ='Calc 1'!E267 -> 0 | E6: ='Calc 1'!F267 -> 0 | F6: ='Budget show 1'!I19 -> 0 | G6: =E6-F6 -> 0 | I6: ='Budget show 1'!E10 -> 0 | J6: =E6/I6 -> #DIV/0!
B7: ='Budget show 2'!E5 -> show | C7: ='Calc 2'!D267 -> 1 | D7: ='Calc 2'!E267 -> 4 | E7: ='Calc 2'!F267 -> 5 | F7: ='Budget show 2'!I19 -> 0 | G7: =E7-F7 -> 5 | I7: ='Budget show 2'!E10 -> 0 | J7: =E7/I7 -> #DIV/0!
B8: ='Budget show 3'!E5 -> show | C8: ='Calc 3'!D267 -> 0 | D8: ='Calc 3'!E267 -> 0 | E8: ='Calc 3'!F267 -> 0 | F8: ='Budget show 3'!I19 -> 0 | G8: =E8-F8 -> 0 | I8: ='Budget show 3'!E10 -> 0 | J8: =E8/I8 -> #DIV/0!
B9: ='Budget show 4'!E5 -> show | C9: ='Calc 4'!D267 -> 0 | D9: ='Calc 4'!E267 -> 0 | E9: ='Calc 4'!F267 -> 0 | F9: ='Budget show 4'!I19 -> 0 | G9: =E9-F9 -> 0 | I9: ='Budget show 4'!E10 -> 0 | J9: =E9/I9 -> #DIV/0!
B12: Total overview | C12: =SUM(C6:C10) -> 1 | D12: =SUM(D6:D10) -> 4 | E12: =SUM(E6:E10) -> 5 | F12: =SUM(F6:F9) -> 0 | G12: =SUM(G6:G9) -> 5 | I12: =SUM(I6:I10) -> 0 | J12: =E12/I12 -> #DIV/0!
D13: =E12-C12 -> 4
D14: =D13/E12 -> 0.8
C18: Package discount | E18: Package discount
C19: 0 | D19: =E19-C19 -> 0 | E19: 0 | F19: =E19/E12 -> 0
E21: Total package | F21: Budget | G21: Difference
C22: =C12+C19 -> 1 | D22: =D12+D19 -> 4 | E22: =E12+E19 -> 5 | F22: =F12 -> 0 | G22: =E22-F22 -> 5
D23: =D22/E22 -> 0.8 | G23: =G22/F22 -> #DIV/0!
C26: Margin/show | D26: =D22/D3 -> 1

Sheet Rapportage
B3: Margin stand | C3: In Euro | D3: In %
B4: Budget | C4: ='Budget show 1'!G63 -> 0 | D4: ='Budget show 1'!G64 -> 0
B5: Calculated | C5: ='Calc 1'!E233 -> 0 | D5: ='Calc 1'!E235 -> 0
B6: Final margin | C6: 8039.86 | D6: 0.295
B22: PM costs | C22: In Euro
B23: Budget | C23: ='Budget show 1'!E46 -> 0
B24: Calculated | C24: ='Calc 1'!D216 -> 0
B25: Actual spend | C25: 841.14

Sheet Dropdown content
A1: Country
A2: <kies land> | D2: <kies type>
A3: Afghanistan | D3: single deck
A4: Albania | D4: double deck
A5: Algeria
A6: Andorra | D6: <kies type>
A7: Angola | D7: island stand
A8: Antigua and Barbuda | D8: head stand
A9: Argentina | D9: corner stand
A10: Armenia | D10: row stand
A11: Australia | D11: other
A12: Austria
A13: Azerbaijan
A14: Bahamas
A15: Bahrain
A16: Bangladesh
A17: Barbados
A18: Belarus
A19: Belgium
A20: Belize
A21: Benin
A22: Bhutan
A23: Bolivia
... A195: Zimbabwe

Sheet Nacalculatie
